<?xml version="1.0"?>
<robot xmlns:xacro="http://www.ros.org/wiki/xacro">
            <!--SETUP HINH DANG ROBOT O DAY-->
            <xacro:include filename="inertial_macros.xacro"/>           <!--Dinh nghia cac qua'n ti'nh robot-->
    <!-- dat cac mau cho robot-->
    <material name = "white">
        <color rgba="1 1 1 1" />
    </material>      
    
    <material name = "orange">
        <color rgba="1 0.3 0.1 1" />
    </material> 

    <material name = "blue">
        <color rgba="0.2 0.2 1 1" />
    </material> 

    <material name = "black">
        <color rgba="0 0 0 1" />
    </material> 

    <!--base link-->

    <link name="base_link">
    </link>

    <!--Chassis link-->
    <!--joint cac thanh phan-->
    <joint name="chassis_joint" type="fixed">
        <parent link="base_link"/>
        <child link="chassis"/>   
        <!--tam robot doi lui x = -0.1 vi 2 banh nam sau than xe-->
        <origin xyz="-0.1 0.0 0.0"/>
                  
    </joint>
    <link name = "chassis">
        <visual>
            <origin xyz="0.15 0 0.075" rpy="0 0 0"/>        <!-- doi goc toa do ve toa do nay de cho 1/2 banh xe ve duoi than-->
            <geometry>
                <box size="0.3 0.3 0.15"/>          <!--than robot tinh theo met-->
            </geometry> 
            <material name = "white"/>          <!--than xe mau trang-->
        </visual>
        <collision>                             <!--sap xep cac va cham-->              
            <origin xyz="0.15 0 0.075" rpy="0 0 0"/>        <!-- doi goc toa do ve toa do nay de cho 1/2 banh xe ve duoi than-->
            <geometry>
                <box size="0.3 0.3 0.15"/>          <!--than robot tinh theo met-->
            </geometry> 
        </collision>    
        <!-- cac macro quan tinh dinh nghia tren include them vao o day-->
        <xacro:inertial_box mass = "0.5" x= "0.3" y="0.3" z ="0.15">
            <origin xyz="0.15 0 0.075" rpy="0 0 0 "/>
        </xacro:inertial_box>
            
                
    </link>

    <!--LEFT WHELL LINK -->
    <joint name="left_wheel_joint" type="continuous">
        <parent link="base_link"/>
        <child link="left_wheel"/>
        <origin xyz="0 0.175 0" rpy="-${pi/2} 0 0"/>
        <axis xyz="0 0 1"/>             <!--de quay banh xe theo truc z cho khop than xe-->
    </joint>

    <link name="left_wheel">            <!--Hinh dang banh xe-->
        <visual>
            <geometry>
                <cylinder length="0.04" radius="0.05" />
            </geometry>
            <material name="blue"/>
        </visual>

        <collision>                     <!--sap xep cac va cham-->
            <geometry>
                <cylinder length="0.04" radius="0.05" />
            </geometry>
        </collision>

        <!--macro quan tinh-->
        <xacro:inertial_cylinder mass="0.1" length="0.04" radius="0.05">
            <origin xyz="0 0 0" rpy="0 0 0"/>
        </xacro:inertial_cylinder>

    </link>

    <!--RIGH WHELL LINK -->
    <joint name="right_wheel_joint" type="continuous">
        <parent link="base_link"/>
        <child link="right_wheel"/>
        <origin xyz="0 -0.175 0" rpy="${pi/2} 0 0"/>
        <axis xyz="0 0 -1"/>
    </joint>

    <link name="right_wheel">
        <visual>
            <geometry>
                <cylinder length="0.04" radius="0.05" />
            </geometry>
            <material name="blue"/>
        </visual>

        <collision>
            <geometry>
                <cylinder length="0.04" radius="0.05" />
            </geometry>
        </collision>
         <!--macro quan tinh-->
        <xacro:inertial_cylinder mass="0.1" length="0.04" radius="0.05">
            <origin xyz="0 0 0" rpy="0 0 0"/>
        </xacro:inertial_cylinder>
    </link>

    <!-- CASTER WHEEL -->

    <joint name="caster_wheel_joint" type="fixed">
        <parent link="chassis"/>
        <child link="caster_wheel"/>
        <origin xyz="0.24 0 0" rpy="0 0 0"/>
    </joint>

    <link name="caster_wheel">
        <visual>
            <geometry>
                <sphere radius="0.05" />
            </geometry>
            <material name="black"/>
        </visual>
        <collision>                 <!--va cham-->
            <geometry>
                <sphere radius="0.05" />
            </geometry>
            <material name="black"/>
        </collision>
        <xacro:inertial_sphere mass = "0.1" radius = "0.05">        <!--quan tinh-->
            <origin xyz="0 0 0" rpy="0 0 0"/>
        </xacro:inertial_sphere >
    </link>
</robot>